Workbook

Sheet Atracción 1.1 (TripAdvisor)
A1: ID | B1: Categoría del Recurso | C1: Recurso | D1: Origen | E1: V1​a Masa Crítica - Google (Contraste) (Número de Reseñas) | F1: V1​b Masa Crítica - TripAdvisor (Origen) (Número de Reseñas) | G1: V2a​ Calidad - Google (Contraste) (Puntuación 0-5) | H1: V2b​ Calidad - TripAdvisor (Origen) (Puntuación 0-5) | I1: V2 Ponderada | J1: V3​ Ranking - TripAdvisor | K1: V4a​ Grado de Presencia Algorítmica (web) | L1: V4b Grado de Presencia Algorítmica (maps libre) | M1: V4c​ Grado de Presencia Algorítmica (maps forzado) | N1: V4 Ponderada | O1: V5 Proximidad al Punto 0 (Metros) | P1: V6a Desviación Calidad (Contraste-Origen) | Q1: V6b Desviación de Calidad (Contraste-Ponderada) | R1: V6c Desviación de Calidad (Origen-Ponderada) | S1: V7 Grado de atención turística digital según ubicación | T1: V8 Grado de capital reputacional digital | U1: V9a Grado de Visibilidad Espacial Algorítmica en web | V1: V9b Grado de Visibilidad Espacial Algorítmica en maps libre | W1: V9c Grado de Visibilidad Espacial Algorítmica en maps forzado | X1: V10 Grado de Ventaja Algorítmica entre Plataformas | Y1: V9 Ponderada | Z1: V11a Grado de Presión Turística Digital según web | AA1: V11b Grado de Presión Turística Digital según maps libre | AB1: V11c Grado de Presión Turística Digital según maps forzado | AC1: V11 Ponderada
A2: 1 | B2: Atracción Turística | C2: Plaza de España | D2: TripAdvisor | E2: 181284 | F2: 45480 | G2: 4.8 | H2: 4.8 | I2: =((G2*E2)+(H2*F2))/SUM(E2,F2) -> 4.8 | J2: 1 | K2: 0 | L2: 0 | M2: 0 | N2: =(K2*0.5)+(L2*0.4)+(M2*0.1) -> 0 | O2: 1120 | P2: =ABS(G2-H2) -> 0 | Q2: =ABS(H2-I2) -> 0 | R2: =ABS(H2-I2) -> 0 | S2: =SUM(E2,F2)/O2 -> 202.46786 | T2: =LOG10(E2+F2)*I2 -> 25.706756 | U2: =(K2/O2)*100 -> 0 | V2: =(L2/O2)*100 -> 0 | W2: =(M2/O2)*100 -> 0 | X2: =E2/F2 -> 3.9860158 | Y2: =(N2/O2)*100 -> 0 | Z2: =(SUM(E2,F2)/(K2+0.1))/100 -> 22676.4 | AA2: =(SUM(E2,F2)/(L2+0.1))/100 -> 22676.4 | AB2: =(SUM(E2,F2)/(M2+0.1))/100 -> 22676.4 | AC2: =(SUM(E2,F2)/(N2+0.1))/100 -> 22676.4
A3: =A2+1 -> 2 | B3: Atracción Turística | C3: Real Alcázar de Sevilla | D3: TripAdvisor | E3: 98150 | F3: 36806 | G3: 4.7 | H3: 4.7 | I3: =((G3*E3)+(H3*F3))/SUM(E3,F3) -> 4.7 | J3: 2 | K3: 0 | L3: 0 | M3: 0 | N3: =(K3*0.5)+(L3*0.4)+(M3*0.1) -> 0 | O3: 400 | P3: =ABS(G3-H3) -> 0 | Q3: =ABS(G3-I3) -> 8.8817842e-16 | R3: =ABS(H3-I3) -> 8.8817842e-16 | S3: =SUM(E3,F3)/O3 -> 337.39 | T3: =LOG10(E3+F3)*I3 -> 24.111903 | U3: =(K3/O3)*100 -> 0 | V3: =(L3/O3)*100 -> 0 | W3: =(M3/O3)*100 -> 0 | X3: =E3/F3 -> 2.6666848 | Y3: =(N3/O3)*100 -> 0 | Z3: =(SUM(E3,F3)/(K3+0.1))/100 -> 13495.6 | AA3: =(SUM(E3,F3)/(L3+0.1))/100 -> 13495.6 | AB3: =(SUM(E3,F3)/(M3+0.1))/100 -> 13495.6 | AC3: =(SUM(E3,F3)/(N3+0.1))/100 -> 13495.6
A4: =A3+1 -> 3 | B4: Atracción Turística | C4: Catedral de Sevilla | D4: TripAdvisor | E4: 57330 | F4: 27294 | G4: 4.8 | H4: 4.6 | I4: =((G4*E4)+(H4*F4))/SUM(E4,F4) -> 4.7354935 | J4: 3 | K4: 0 | L4: 0 | M4: 0 | N4: =(K4*0.5)+(L4*0.4)+(M4*0.1) -> 0 | O4: 59 | P4: =ABS(G4-H4) -> 0.2 | Q4: =ABS(G4-I4) -> 0.064506523 | R4: =ABS(H4-I4) -> 0.13549348 | S4: =SUM(E4,F4)/O4 -> 1434.3051 | T4: =LOG10(E4+F4)*I4 -> 23.334114 | U4: =(K4/O4)*100 -> 0 | V4: =(L4/O4)*100 -> 0 | W4: =(M4/O4)*100 -> 0 | X4: =E4/F4 -> 2.1004616 | Y4: =(N4/O4)*100 -> 0 | Z4: =(SUM(E4,F4)/(K4+0.1))/100 -> 8462.4 | AA4: =(SUM(E4,F4)/(L4+0.1))/100 -> 8462.4 | AB4: =(SUM(E4,F4)/(M4+0.1))/100 -> 8462.4 | AC4: =(SUM(E4,F4)/(N4+0.1))/100 -> 8462.4
A5: =A4+1 -> 4 | B5: Atracción Turística | C5: Setas de Sevilla | D5: TripAdvisor | E5: 105610 | F5: 11354 | G5: 4.4 | H5: 4 | I5: =((G5*E5)+(H5*F5))/SUM(E5,F5) -> 4.361171 | J5: 5 | K5: 150 | L5: 0 | M5: 0 | N5: =(K5*0.5)+(L5*0.4)+(M5*0.1) -> 75 | O5: 793 | P5: =ABS(G5-H5) -> 0.4 | Q5: =ABS(G5-I5) -> 0.038829041 | R5: =ABS(H5-I5) -> 0.36117096 | S5: =SUM(E5,F5)/O5 -> 147.49559 | T5: =LOG10(E5+F5)*I5 -> 22.102642 | U5: =(K5/O5)*100 -> 18.915511 | V5: =(L5/O5)*100 -> 0 | W5: =(M5/O5)*100 -> 0 | X5: =E5/F5 -> 9.3015677 | Y5: =(N5/O5)*100 -> 9.4577554 | Z5: =(SUM(E5,F5)/(K5+0.1))/100 -> 7.7924051 | AA5: =(SUM(E5,F5)/(L5+0.1))/100 -> 11696.4 | AB5: =(SUM(E5,F5)/(M5+0.1))/100 -> 11696.4 | AC5: =(SUM(E5,F5)/(N5+0.1))/100 -> 15.574434
A6: =A5+1 -> 5 | B6: Atracción Turística | C6: Parque de María Luisa | D6: TripAdvisor | E6: 41265 | F6: 7162 | G6: 4.8 | H6: 4.5 | I6: =((G6*E6)+(H6*F6))/SUM(E6,F6) -> 4.7556322 | J6: 6 | K6: 1500 | L6: 0 | M6: 0 | N6: =(K6*0.5)+(L6*0.4)+(M6*0.1) -> 750 | O6: 1450 | P6: =ABS(G6-H6) -> 0.3 | Q6: =ABS(G6-I6) -> 0.044367811 | R6: =ABS(H6-I6) -> 0.25563219 | S6: =SUM(E6,F6)/O6 -> 33.397931 | T6: =LOG10(E6+F6)*I6 -> 22.280553 | U6: =(K6/O6)*100 -> 103.44828 | V6: =(L6/O6)*100 -> 0 | W6: =(M6/O6)*100 -> 0 | X6: =E6/F6 -> 5.7616588 | Y6: =(N6/O6)*100 -> 51.724138 | Z6: =(SUM(E6,F6)/(K6+0.1))/100 -> 0.32282514 | AA6: =(SUM(E6,F6)/(L6+0.1))/100 -> 4842.7 | AB6: =(SUM(E6,F6)/(M6+0.1))/100 -> 4842.7 | AC6: =(SUM(E6,F6)/(N6+0.1))/100 -> 0.64560725
A7: =A6+1 -> 6 | B7: Atracción Turística | C7: La Giralda (Punto 0) | D7: TripAdvisor | E7: 55912 | F7: 11034 | G7: 4.7 | H7: 4.6 | I7: =((G7*E7)+(H7*F7))/SUM(E7,F7) -> 4.6835181 | J7: 7 | K7: 0 | L7: 1683 | M7: 100 | N7: =(K7*0.5)+(L7*0.4)+(M7*0.1) -> 683.2 | O7: 0.01 | P7: =ABS(G7-H7) -> 0.1 | Q7: =ABS(G7-I7) -> 0.016481941 | R7: =ABS(H7-I7) -> 0.083518059 | S7: =SUM(E7,F7)/O7 -> 6694600 | T7: =LOG10(E7+F7)*I7 -> 22.601368 | U7: =(K7/O7)*100 -> 0 | V7: =(L7/O7)*100 -> 16830000 | W7: =(M7/O7)*100 -> 1000000 | X7: =E7/F7 -> 5.0672467 | Y7: =(N7/O7)*100 -> 6832000 | Z7: =(SUM(E7,F7)/(K7+0.1))/100 -> 6694.6 | AA7: =(SUM(E7,F7)/(L7+0.1))/100 -> 0.39775414 | AB7: =(SUM(E7,F7)/(M7+0.1))/100 -> 6.6879121 | AC7: =(SUM(E7,F7)/(N7+0.1))/100 -> 0.97974535
A8: =A7+1 -> 7 | B8: Atracción Turística | C8: Casa de Pilatos | D8: TripAdvisor | E8: 13802 | F8: 3929 | G8: 4.4 | H8: 4.3 | I8: =((G8*E8)+(H8*F8))/SUM(E8,F8) -> 4.3778411 | J8: 8 | K8: 0 | L8: 0 | M8: 0 | N8: =(K8*0.5)+(L8*0.4)+(M8*0.1) -> 0 | O8: 641 | P8: =ABS(G8-H8) -> 0.1 | Q8: =ABS(G8-I8) -> 0.022158931 | R8: =ABS(H8-I8) -> 0.077841069 | S8: =SUM(E8,F8)/O8 -> 27.661466 | T8: =LOG10(E8+F8)*I8 -> 18.600279 | U8: =(K8/O8)*100 -> 0 | V8: =(L8/O8)*100 -> 0 | W8: =(M8/O8)*100 -> 0 | X8: =E8/F8 -> 3.5128531 | Y8: =(N8/O8)*100 -> 0 | Z8: =(SUM(E8,F8)/(K8+0.1))/100 -> 1773.1 | AA8: =(SUM(E8,F8)/(L8+0.1))/100 -> 1773.1 | AB8: =(SUM(E8,F8)/(M8+0.1))/100 -> 1773.1 | AC8: =(SUM(E8,F8)/(N8+0.1))/100 -> 1773.1
A9: =A8+1 -> 8 | B9: Atracción Turística | C9: Mercado de Triana | D9: TripAdvisor | E9: 10654 | F9: 1132 | G9: 4.4 | H9: 4 | I9: =((G9*E9)+(H9*F9))/SUM(E9,F9) -> 4.3615815 | J9: 11 | K9: 0 | L9: 0 | M9: 0 | N9: =(K9*0.5)+(L9*0.4)+(M9*0.1) -> 0 | O9: 974 | P9: =ABS(G9-H9) -> 0.4 | Q9: =ABS(G9-I9) -> 0.038418463 | R9: =ABS(H9-I9) -> 0.36158154 | S9: =SUM(E9,F9)/O9 -> 12.100616 | T9: =LOG10(E9+F9)*I9 -> 17.757597 | U9: =(K9/O9)*100 -> 0 | V9: =(L9/O9)*100 -> 0 | W9: =(M9/O9)*100 -> 0 | X9: =E9/F9 -> 9.4116608 | Y9: =(N9/O9)*100 -> 0 | Z9: =(SUM(E9,F9)/(K9+0.1))/100 -> 1178.6 | AA9: =(SUM(E9,F9)/(L9+0.1))/100 -> 1178.6 | AB9: =(SUM(E9,F9)/(M9+0.1))/100 -> 1178.6 | AC9: =(SUM(E9,F9)/(N9+0.1))/100 -> 1178.6
A10: =A9+1 -> 9 | B10: Atracción Turística | C10: Museo de Bellas Artes | D10: TripAdvisor | E10: 16014 | F10: 2218 | G10: 4.7 | H10: 4.4 | I10: =((G10*E10)+(H10*F10))/SUM(E10,F10) -> 4.6635037 | J10: 12 | K10: 0 | L10: 0 | M10: 0 | N10: =(K10*0.5)+(L10*0.4)+(M10*0.1) -> 0 | O10: 962 | P10: =ABS(G10-H10) -> 0.3 | Q10: =ABS(G10-I10) -> 0.03649627 | R10: =ABS(H10-I10) -> 0.26350373 | S10: =SUM(E10,F10)/O10 -> 18.952183 | T10: =LOG10(E10+F10)*I10 -> 19.870417 | U10: =(K10/O10)*100 -> 0 | V10: =(L10/O10)*100 -> 0 | W10: =(M10/O10)*100 -> 0 | X10: =E10/F10 -> 7.220018 | Y10: =(N10/O10)*100 -> 0 | Z10: =(SUM(E10,F10)/(K10+0.1))/100 -> 1823.2 | AA10: =(SUM(E10,F10)/(L10+0.1))/100 -> 1823.2 | AB10: =(SUM(E10,F10)/(M10+0.1))/100 -> 1823.2 | AC10: =(SUM(E10,F10)/(N10+0.1))/100 -> 1823.2
A11: =A10+1 -> 10 | B11: Atracción Turística | C11: Real Maestranza de Caballería | D11: TripAdvisor | E11: 31701 | F11: 5718 | G11: 4.4 | H11: 4.1 | I11: =((G11*E11)+(H11*F11))/SUM(E11,F11) -> 4.354157 | J11: 13 | K11: 0 | L11: 0 | M11: 0 | N11: =(K11*0.5)+(L11*0.4)+(M11*0.1) -> 0 | O11: 553 | P11: =ABS(G11-H11) -> 0.3 | Q11: =ABS(G11-I11) -> 0.045843021 | R11: =ABS(H11-I11) -> 0.25415698 | S11: =SUM(E11,F11)/O11 -> 67.665461 | T11: =LOG10(E11+F11)*I11 -> 19.911961 | U11: =(K11/O11)*100 -> 0 | V11: =(L11/O11)*100 -> 0 | W11: =(M11/O11)*100 -> 0 | X11: =E11/F11 -> 5.5440714 | Y11: =(N11/O11)*100 -> 0 | Z11: =(SUM(E11,F11)/(K11+0.1))/100 -> 3741.9 | AA11: =(SUM(E11,F11)/(L11+0.1))/100 -> 3741.9 | AB11: =(SUM(E11,F11)/(M11+0.1))/100 -> 3741.9 | AC11: =(SUM(E11,F11)/(N11+0.1))/100 -> 3741.9
A12: =A11+1 -> 11 | B12: Atracción Turística | C12: Basílica de la Macarena | D12: TripAdvisor | E12: 3506 | F12: 2484 | G12: 4.8 | H12: 4.4 | I12: =((G12*E12)+(H12*F12))/SUM(E12,F12) -> 4.6341235 | J12: 14 | K12: 0 | L12: 0 | M12: 0 | N12: =(K12*0.5)+(L12*0.4)+(M12*0.1) -> 0 | O12: 1850 | P12: =ABS(G12-H12) -> 0.4 | Q12: =ABS(G12-I12) -> 0.16587646 | R12: =ABS(H12-I12) -> 0.23412354 | S12: =SUM(E12,F12)/O12 -> 3.2378378 | T12: =LOG10(E12+F12)*I12 -> 17.505063 | U12: =(K12/O12)*100 -> 0 | V12: =(L12/O12)*100 -> 0 | W12: =(M12/O12)*100 -> 0 | X12: =E12/F12 -> 1.4114332 | Y12: =(N12/O12)*100 -> 0 | Z12: =(SUM(E12,F12)/(K12+0.1))/100 -> 599 | AA12: =(SUM(E12,F12)/(L12+0.1))/100 -> 599 | AB12: =(SUM(E12,F12)/(M12+0.1))/100 -> 599 | AC12: =(SUM(E12,F12)/(N12+0.1))/100 -> 599
A13: =A12+1 -> 12 | B13: Atracción Turística | C13: Isla Mágica | D13: TripAdvisor | E13: 32790 | F13: 2730 | G13: 4.1 | H13: 3.6 | I13: =((G13*E13)+(H13*F13))/SUM(E13,F13) -> 4.0615709 | J13: 15 | K13: 8 | L13: 0 | M13: 0 | N13: =(K13*0.5)+(L13*0.4)+(M13*0.1) -> 4 | O13: 2260 | P13: =ABS(G13-H13) -> 0.5 | Q13: =ABS(G13-I13) -> 0.038429054 | R13: =ABS(H13-I13) -> 0.46157095 | S13: =SUM(E13,F13)/O13 -> 15.716814 | T13: =LOG10(E13+F13)*I13 -> 18.482069 | U13: =(K13/O13)*100 -> 0.3539823 | V13: =(L13/O13)*100 -> 0 | W13: =(M13/O13)*100 -> 0 | X13: =E13/F13 -> 12.010989 | Y13: =(N13/O13)*100 -> 0.17699115 | Z13: =(SUM(E13,F13)/(K13+0.1))/100 -> 43.851852 | AA13: =(SUM(E13,F13)/(L13+0.1))/100 -> 3552 | AB13: =(SUM(E13,F13)/(M13+0.1))/100 -> 3552 | AC13: =(SUM(E13,F13)/(N13+0.1))/100 -> 86.634146
A14: =A13+1 -> 13 | B14: Atracción Turística | C14: Museo de las Ilusiones de Sevilla | D14: TripAdvisor | E14: 4771 | F14: 527 | G14: 4.5 | H14: 4.7 | I14: =((G14*E14)+(H14*F14))/SUM(E14,F14) -> 4.5198943 | J14: 16 | K14: 0 | L14: 0 | M14: 0 | N14: =(K14*0.5)+(L14*0.4)+(M14*0.1) -> 0 | O14: 743 | P14: =ABS(G14-H14) -> 0.2 | Q14: =ABS(G14-I14) -> 0.0198943 | R14: =ABS(H14-I14) -> 0.1801057 | S14: =SUM(E14,F14)/O14 -> 7.1305518 | T14: =LOG10(E14+F14)*I14 -> 16.832592 | U14: =(K14/O14)*100 -> 0 | V14: =(L14/O14)*100 -> 0 | W14: =(M14/O14)*100 -> 0 | X14: =E14/F14 -> 9.0531309 | Y14: =(N14/O14)*100 -> 0 | Z14: =(SUM(E14,F14)/(K14+0.1))/100 -> 529.8 | AA14: =(SUM(E14,F14)/(L14+0.1))/100 -> 529.8 | AB14: =(SUM(E14,F14)/(M14+0.1))/100 -> 529.8 | AC14: =(SUM(E14,F14)/(N14+0.1))/100 -> 529.8
... A26: =A25+1 -> 25 | B26: Atracción Turística | C26: Torre del Oro | D26: TripAdvisor | E26: 53575 | F26: 2469 | G26: 4.5 | H26: 3.9 | I26: =((G26*E26)+(H26*F26))/SUM(E26,F26) -> 4.4735672 | J26: 33 | K26: 0 | L26: 0 | M26: 0 | N26: =(K26*0.5)+(L26*0.4)+(M26*0.1) -> 0 | O26: 522 | P26: =ABS(G26-H26) -> 0.6 | Q26: =ABS(G26-I26) -> 0.026432803 | R26: =ABS(H26-I26) -> 0.5735672 | S26: =SUM(E26,F26)/O26 -> 107.36398 | T26: =LOG10(E26+F26)*I26 -> 21.242864 | U26: =(K26/O26)*100 -> 0 | V26: =(L26/O26)*100 -> 0 | W26: =(M26/O26)*100 -> 0 | X26: =E26/F26 -> 21.699068 | Y26: =(N26/O26)*100 -> 0 | Z26: =(SUM(E26,F26)/(K26+0.1))/100 -> 5604.4 | AA26: =(SUM(E26,F26)/(L26+0.1))/100 -> 5604.4 | AB26: =(SUM(E26,F26)/(M26+0.1))/100 -> 5604.4 | AC26: =(SUM(E26,F26)/(N26+0.1))/100 -> 5604.4
B28: INFO

Sheet Atracción 1.3 (Intrusos LP)
A1: ID | B1: Categoría del Recurso | C1: Recurso | D1: Origen | E1: V1​a Masa Crítica - Google (Contraste) (Número de Reseñas) | F1: V1​b Masa Crítica - TripAdvisor (Origen) (Número de Reseñas) | G1: V2a​ Calidad - Google (Contraste) (Puntuación 0-5) | H1: V2b​ Calidad - TripAdvisor (Origen) (Puntuación 0-5) | I1: V2 Ponderada | J1: V3​ Ranking - TripAdvisor | K1: V4a​ Grado de Presencia Algorítmica (web) | L1: V4b Grado de Presencia Algorítmica (maps libre) | M1: V4c​ Grado de Presencia Algorítmica (maps forzado) | N1: V4 Ponderada | O1: V5 Proximidad al Punto 0 (Metros) | P1: V6a Desviación Calidad (Contraste-Origen) | Q1: V6b Desviación de Calidad (Contraste-Ponderada) | R1: V6c Desviación de Calidad (Origen-Ponderada) | S1: V7 Grado de atención turística digital según ubicación | T1: V8 Grado de capital reputacional digital | U1: V9 Grado de Visibilidad Espacial Algorítmica en web | V1: V9 Grado de Visibilidad Espacial Algorítmica en maps libre | W1: V9 Grado de Visibilidad Espacial Algorítmica en maps libre | X1: V9 Ponderada | Y1: V10 Grado de Ventaja Algorítmica entre Plataformas | Z1: V11a Grado de Presión Turística Digital según web | AA1: V11b Grado de Presión Turística Digital según maps libre | AB1: V11c Grado de Presión Turística Digital según maps forzado | AC1: V11 Ponderada
A2: ='Atracción 1.1 (TripAdvisor)'!A26+1 -> 26 | B2: Atracción Turística | C2: Parque de los Descubrimientos | D2: Intruso | E2: 1503 | F2: 1 | G2: 4.3 | H2: 0 | I2: =((G2*E2)+(H2*F2))/SUM(E2,F2) -> 4.297141 | J2: - | K2: 806 | L2: 0 | M2: 0 | N2: =(K2*0.5)+(L2*0.4)+(M2*0.1) -> 403 | O2: 1540 | P2: =ABS(G2-H2) -> 4.3 | Q2: =ABS(H2-I2) -> 4.297141 | R2: =ABS(H2-I2) -> 4.297141 | S2: =SUM(E2,F2)/O2 -> 0.97662338 | T2: =LOG10(E2+F2)*I2 -> 13.653082 | U2: =(K2/O2)*100 -> 52.337662 | V2: =(L2/O2)*100 -> 0 | W2: =(M2/O2)*100 -> 0 | X2: =(N2/O2)*100 -> 26.168831 | Y2: =E2/F2 -> 1503 | Z2: =(SUM(E2,F2)/(K2+0.1))/100 -> 0.018657735 | AA2: =(SUM(E2,F2)/(L2+0.1))/100 -> 150.4 | AB2: =(SUM(E2,F2)/(M2+0.1))/100 -> 150.4 | AC2: =(SUM(E2,F2)/(N2+0.1))/100 -> 0.037310841
A3: =A2+1 -> 27 | B3: Atracción Turística | C3: Estanque Central de Plaza de América | D3: Intruso | E3: 52 | F3: 657 | G3: 4.8 | H3: 4.4 | I3: =((G3*E3)+(H3*F3))/SUM(E3,F3) -> 4.4293371 | J3: 40 | K3: 537 | L3: 93 | M3: 0 | N3: =(K3*0.5)+(L3*0.4)+(M3*0.1) -> 305.7 | O3: 1700 | P3: =ABS(G3-H3) -> 0.4 | Q3: =ABS(H3-I3) -> 0.029337094 | R3: =ABS(H3-I3) -> 0.029337094 | S3: =SUM(E3,F3)/O3 -> 0.41705882 | T3: =LOG10(E3+F3)*I3 -> 12.626473 | U3: =(K3/O3)*100 -> 31.588235 | V3: =(L3/O3)*100 -> 5.4705882 | W3: =(M3/O3)*100 -> 0 | X3: =(N3/O3)*100 -> 17.982353 | Y3: =E3/F3 -> 0.079147641 | Z3: =(SUM(E3,F3)/(K3+0.1))/100 -> 0.013200521 | AA3: =(SUM(E3,F3)/(L3+0.1))/100 -> 0.076154672 | AB3: =(SUM(E3,F3)/(M3+0.1))/100 -> 70.9 | AC3: =(SUM(E3,F3)/(N3+0.1))/100 -> 0.023185088
A4: =A3+1 -> 28 | B4: Atracción Turística | C4: Torre Sur | D4: Intruso | E4: 165 | F4: 3 | G4: 4.8 | H4: 4.3 | I4: =((G4*E4)+(H4*F4))/SUM(E4,F4) -> 4.7910714 | J4: 254 | K4: 347 | L4: 0 | M4: 0 | N4: =(K4*0.5)+(L4*0.4)+(M4*0.1) -> 173.5 | O4: 1250 | P4: =ABS(G4-H4) -> 0.5 | Q4: =ABS(H4-I4) -> 0.49107143 | R4: =ABS(H4-I4) -> 0.49107143 | S4: =SUM(E4,F4)/O4 -> 0.1344 | T4: =LOG10(E4+F4)*I4 -> 10.661616 | U4: =(K4/O4)*100 -> 27.76 | V4: =(L4/O4)*100 -> 0 | W4: =(M4/O4)*100 -> 0 | X4: =(N4/O4)*100 -> 13.88 | Y4: =E4/F4 -> 55 | Z4: =(SUM(E4,F4)/(K4+0.1))/100 -> 0.0048401037 | AA4: =(SUM(E4,F4)/(L4+0.1))/100 -> 16.8 | AB4: =(SUM(E4,F4)/(M4+0.1))/100 -> 16.8 | AC4: =(SUM(E4,F4)/(N4+0.1))/100 -> 0.0096774194
A5: =A4+1 -> 29 | B5: Atracción Turística | C5: Mosaico Guadalquivir | D5: Intruso | E5: 21 | F5: 1 | G5: 4.5 | H5: 0 | I5: =((G5*E5)+(H5*F5))/SUM(E5,F5) -> 4.2954545 | J5: - | K5: 182 | L5: 0 | M5: 0 | N5: =(K5*0.5)+(L5*0.4)+(M5*0.1) -> 91 | O5: 864 | P5: =ABS(G5-H5) -> 4.5 | Q5: =ABS(H5-I5) -> 4.2954545 | R5: =ABS(H5-I5) -> 4.2954545 | S5: =SUM(E5,F5)/O5 -> 0.025462963 | T5: =LOG10(E5+F5)*I5 -> 5.7663156 | U5: =(K5/O5)*100 -> 21.064815 | V5: =(L5/O5)*100 -> 0 | W5: =(M5/O5)*100 -> 0 | X5: =(N5/O5)*100 -> 10.532407 | Y5: =E5/F5 -> 21 | Z5: =(SUM(E5,F5)/(K5+0.1))/100 -> 0.0012081274 | AA5: =(SUM(E5,F5)/(L5+0.1))/100 -> 2.2 | AB5: =(SUM(E5,F5)/(M5+0.1))/100 -> 2.2 | AC5: =(SUM(E5,F5)/(N5+0.1))/100 -> 0.0024149286
A6: =A5+1 -> 30 | B6: Atracción Turística | C6: Fuente de las Cuatro Estaciones | D6: Intruso | E6: 46 | F6: 17 | G6: 4.7 | H6: 3.7 | I6: =((G6*E6)+(H6*F6))/SUM(E6,F6) -> 4.4301587 | J6: 187 | K6: 13 | L6: 390 | M6: 0 | N6: =(K6*0.5)+(L6*0.4)+(M6*0.1) -> 162.5 | O6: 671 | P6: =ABS(G6-H6) -> 1 | Q6: =ABS(H6-I6) -> 0.73015873 | R6: =ABS(H6-I6) -> 0.73015873 | S6: =SUM(E6,F6)/O6 -> 0.093889717 | T6: =LOG10(E6+F6)*I6 -> 7.9713642 | U6: =(K6/O6)*100 -> 1.9374069 | V6: =(L6/O6)*100 -> 58.122206 | W6: =(M6/O6)*100 -> 0 | X6: =(N6/O6)*100 -> 24.217586 | Y6: =E6/F6 -> 2.7058824 | Z6: =(SUM(E6,F6)/(K6+0.1))/100 -> 0.048091603 | AA6: =(SUM(E6,F6)/(L6+0.1))/100 -> 0.0016149705 | AB6: =(SUM(E6,F6)/(M6+0.1))/100 -> 6.3 | AC6: =(SUM(E6,F6)/(N6+0.1))/100 -> 0.0038745387
A7: =A6+1 -> 31 | B7: Atracción Turística | C7: Reja del Diablo | D7: Intruso | E7: 64 | F7: 1 | G7: 4.5 | H7: 0 | I7: =((G7*E7)+(H7*F7))/SUM(E7,F7) -> 4.4307692 | J7: - | K7: 0 | L7: 272 | M7: 50 | N7: =(K7*0.5)+(L7*0.4)+(M7*0.1) -> 113.8 | O7: 363 | P7: =ABS(G7-H7) -> 4.5 | Q7: =ABS(H7-I7) -> 4.4307692 | R7: =ABS(H7-I7) -> 4.4307692 | S7: =SUM(E7,F7)/O7 -> 0.17906336 | T7: =LOG10(E7+F7)*I7 -> 8.0326007 | U7: =(K7/O7)*100 -> 0 | V7: =(L7/O7)*100 -> 74.931129 | W7: =(M7/O7)*100 -> 13.774105 | X7: =(N7/O7)*100 -> 31.349862 | Y7: =E7/F7 -> 64 | Z7: =(SUM(E7,F7)/(K7+0.1))/100 -> 6.5 | AA7: =(SUM(E7,F7)/(L7+0.1))/100 -> 0.0023888276 | AB7: =(SUM(E7,F7)/(M7+0.1))/100 -> 0.012974052 | AC7: =(SUM(E7,F7)/(N7+0.1))/100 -> 0.0057067603
A8: =A7+1 -> 32 | B8: Atracción Turística | C8: Monte Gurugú | D8: Intruso | E8: 388 | F8: 1 | G8: 4.4 | H8: 5 | I8: =((G8*E8)+(H8*F8))/SUM(E8,F8) -> 4.4015424 | J8: 355 | K8: 0 | L8: 183 | M8: 133 | N8: =(K8*0.5)+(L8*0.4)+(M8*0.1) -> 86.5 | O8: 1520 | P8: =ABS(G8-H8) -> 0.6 | Q8: =ABS(H8-I8) -> 0.59845758 | R8: =ABS(H8-I8) -> 0.59845758 | S8: =SUM(E8,F8)/O8 -> 0.25592105 | T8: =LOG10(E8+F8)*I8 -> 11.399773 | U8: =(K8/O8)*100 -> 0 | V8: =(L8/O8)*100 -> 12.039474 | W8: =(M8/O8)*100 -> 8.75 | X8: =(N8/O8)*100 -> 5.6907895 | Y8: =E8/F8 -> 388 | Z8: =(SUM(E8,F8)/(K8+0.1))/100 -> 38.9 | AA8: =(SUM(E8,F8)/(L8+0.1))/100 -> 0.021245221 | AB8: =(SUM(E8,F8)/(M8+0.1))/100 -> 0.029226146 | AC8: =(SUM(E8,F8)/(N8+0.1))/100 -> 0.044919169
A9: =A8+1 -> 33 | B9: Atracción Turística | C9: Arco de la Macarena | D9: Intruso | E9: 4300 | F9: 42 | G9: 4.5 | H9: 3.8 | I9: =((G9*E9)+(H9*F9))/SUM(E9,F9) -> 4.4932289 | J9: 107 | K9: 33 | L9: 163 | M9: 150 | N9: =(K9*0.5)+(L9*0.4)+(M9*0.1) -> 96.7 | O9: 1870 | P9: =ABS(G9-H9) -> 0.7 | Q9: =ABS(H9-I9) -> 0.69322893 | R9: =ABS(H9-I9) -> 0.69322893 | S9: =SUM(E9,F9)/O9 -> 2.3219251 | T9: =LOG10(E9+F9)*I9 -> 16.344973 | U9: =(K9/O9)*100 -> 1.7647059 | V9: =(L9/O9)*100 -> 8.7165775 | W9: =(M9/O9)*100 -> 8.0213904 | X9: =(N9/O9)*100 -> 5.171123 | Y9: =E9/F9 -> 102.38095 | Z9: =(SUM(E9,F9)/(K9+0.1))/100 -> 1.3117825 | AA9: =(SUM(E9,F9)/(L9+0.1))/100 -> 0.26621704 | AB9: =(SUM(E9,F9)/(M9+0.1))/100 -> 0.28927382 | AC9: =(SUM(E9,F9)/(N9+0.1))/100 -> 0.44855372
A10: =A9+1 -> 34 | B10: Atracción Turística | C10: Mural "De Viaje" de Cn6 | D10: Intruso | E10: 1 | F10: 1 | G10: 1 | H10: 0 | I10: =((G10*E10)+(H10*F10))/SUM(E10,F10) -> 0.5 | J10: - | K10: 0 | L10: 140 | M10: 0 | N10: =(K10*0.5)+(L10*0.4)+(M10*0.1) -> 56 | O10: 1140 | P10: =ABS(G10-H10) -> 1 | Q10: =ABS(H10-I10) -> 0.5 | R10: =ABS(H10-I10) -> 0.5 | S10: =SUM(E10,F10)/O10 -> 0.001754386 | T10: =LOG10(E10+F10)*I10 -> 0.150515 | U10: =(K10/O10)*100 -> 0 | V10: =(L10/O10)*100 -> 12.280702 | W10: =(M10/O10)*100 -> 0 | X10: =(N10/O10)*100 -> 4.9122807 | Y10: =E10/F10 -> 1 | Z10: =(SUM(E10,F10)/(K10+0.1))/100 -> 0.2 | AA10: =(SUM(E10,F10)/(L10+0.1))/100 -> 0.00014275517 | AB10: =(SUM(E10,F10)/(M10+0.1))/100 -> 0.2 | AC10: =(SUM(E10,F10)/(N10+0.1))/100 -> 0.00035650624
A11: =A10+1 -> 35 | B11: Atracción Turística | C11: Mural "De Viaje" de Kato | D11: Intruso | E11: 0 | F11: 1 | G11: 0 | H11: 0 | I11: 0 | J11: - | K11: 0 | L11: 112 | M11: 25 | N11: =(K11*0.5)+(L11*0.4)+(M11*0.1) -> 47.3 | O11: 1560 | P11: =ABS(G11-H11) -> 0 | Q11: =ABS(H11-I11) -> 0 | R11: =ABS(H11-I11) -> 0 | S11: =SUM(E11,F11)/O11 -> 0.00064102564 | T11: 0 | U11: =(K11/O11)*100 -> 0 | V11: =(L11/O11)*100 -> 7.1794872 | W11: =(M11/O11)*100 -> 1.6025641 | X11: =(N11/O11)*100 -> 3.0320513 | Y11: =E11/F11 -> 0 | Z11: =(SUM(E11,F11)/(K11+0.1))/100 -> 0.1 | AA11: =(SUM(E11,F11)/(L11+0.1))/100 -> 8.9206066e-05 | AB11: =(SUM(E11,F11)/(M11+0.1))/100 -> 0.00039840637 | AC11: =(SUM(E11,F11)/(N11+0.1))/100 -> 0.00021097046
B21: INFO

Sheet Atracciones Turísticas Completo
A1: ID | B1: Categoría del Recurso | C1: Recurso | D1: Origen | E1: V1​a Masa Crítica - Google (Contraste) (Número de Reseñas) | F1: V1​b Masa Crítica - TripAdvisor (Origen) (Número de Reseñas) | G1: V2a​ Calidad - Google (Contraste) (Puntuación 0-5) | H1: V2b​ Calidad - TripAdvisor (Origen) (Puntuación 0-5) | I1: V2 Ponderada | J1: V3 In Ta | K1: V3​ Ranking - TripAdvisor | L1: V4a​ Grado de Presencia Algorítmica (web) | M1: V4b Grado de Presencia Algorítmica (maps libre) | N1: V4c​ Grado de Presencia Algorítmica (maps forzado) | O1: V4 Ponderada | P1: V5 Proximidad al Punto 0 (Metros) | Q1: V6a Desviación Calidad (Contraste-Origen) | R1: V6b Desviación de Calidad (Contraste-Ponderada) | S1: V6c Desviación de Calidad (Origen-Ponderada) | T1: V7 Grado de atención turística digital según ubicación | U1: V8 Grado de capital reputacional digital | V1: V9a Grado de Visibilidad Espacial Algorítmica en web | W1: V9b Grado de Visibilidad Espacial Algorítmica en maps libre | X1: V9c Grado de Visibilidad Espacial Algorítmica en maps forzado | Y1: V9 Ponderada | Z1: V10 Grado de Ventaja Algorítmica entre Plataformas | AA1: V11a Grado de Presión Turística Digital según web | AB1: V11b Grado de Presión Turística Digital según maps libre | AC1: V11c Grado de Presión Turística Digital según maps forzado | AD1: V11 Ponderada
A2: 1 | B2: Atracción Turística | C2: Plaza de España | D2: TripAdvisor | E2: 181284 | F2: 45480 | G2: 4.8 | H2: 4.8 | I2: =((G2*E2)+(H2*F2))/SUM(E2,F2) -> 4.8 | J2: =IF(K2>0,1,0) -> 1 | K2: 1 | L2: 0 | M2: 0 | N2: 0 | O2: =(L2*0.5)+(M2*0.4)+(N2*0.1) -> 0 | P2: 1120 | Q2: =ABS(G2-H2) -> 0 | R2: =ABS(H2-I2) -> 0 | S2: =ABS(H2-I2) -> 0 | T2: =SUM(E2,F2)/P2 -> 202.46786 | U2: =LOG10(E2+F2)*I2 -> 25.706756 | V2: =(L2/P2)*100 -> 0 | W2: =(M2/P2)*100 -> 0 | X2: =(N2/P2)*100 -> 0 | Y2: =(O2/P2)*100 -> 0 | Z2: =E2/F2 -> 3.9860158 | AA2: =(SUM(E2,F2)/(L2+0.1))/100 -> 22676.4 | AB2: =(SUM(E2,F2)/(M2+0.1))/100 -> 22676.4 | AC2: =(SUM(E2,F2)/(N2+0.1))/100 -> 22676.4 | AD2: =(SUM(E2,F2)/(O2+0.1))/100 -> 22676.4
A3: =A2+1 -> 2 | B3: Atracción Turística | C3: Real Alcázar de Sevilla | D3: TripAdvisor | E3: 98150 | F3: 36806 | G3: 4.7 | H3: 4.7 | I3: =((G3*E3)+(H3*F3))/SUM(E3,F3) -> 4.7 | J3: =IF(K3>0,1,0) -> 1 | K3: 2 | L3: 0 | M3: 0 | N3: 0 | O3: =(L3*0.5)+(M3*0.4)+(N3*0.1) -> 0 | P3: 400 | Q3: =ABS(G3-H3) -> 0 | R3: =ABS(G3-I3) -> 8.8817842e-16 | S3: =ABS(H3-I3) -> 8.8817842e-16 | T3: =SUM(E3,F3)/P3 -> 337.39 | U3: =LOG10(E3+F3)*I3 -> 24.111903 | V3: =(L3/P3)*100 -> 0 | W3: =(M3/P3)*100 -> 0 | X3: =(N3/P3)*100 -> 0 | Y3: =(O3/P3)*100 -> 0 | Z3: =E3/F3 -> 2.6666848 | AA3: =(SUM(E3,F3)/(L3+0.1))/100 -> 13495.6 | AB3: =(SUM(E3,F3)/(M3+0.1))/100 -> 13495.6 | AC3: =(SUM(E3,F3)/(N3+0.1))/100 -> 13495.6 | AD3: =(SUM(E3,F3)/(O3+0.1))/100 -> 13495.6
A4: =A3+1 -> 3 | B4: Atracción Turística | C4: Catedral de Sevilla | D4: TripAdvisor | E4: 57330 | F4: 27294 | G4: 4.8 | H4: 4.6 | I4: =((G4*E4)+(H4*F4))/SUM(E4,F4) -> 4.7354935 | J4: =IF(K4>0,1,0) -> 1 | K4: 3 | L4: 0 | M4: 0 | N4: 0 | O4: =(L4*0.5)+(M4*0.4)+(N4*0.1) -> 0 | P4: 59 | Q4: =ABS(G4-H4) -> 0.2 | R4: =ABS(G4-I4) -> 0.064506523 | S4: =ABS(H4-I4) -> 0.13549348 | T4: =SUM(E4,F4)/P4 -> 1434.3051 | U4: =LOG10(E4+F4)*I4 -> 23.334114 | V4: =(L4/P4)*100 -> 0 | W4: =(M4/P4)*100 -> 0 | X4: =(N4/P4)*100 -> 0 | Y4: =(O4/P4)*100 -> 0 | Z4: =E4/F4 -> 2.1004616 | AA4: =(SUM(E4,F4)/(L4+0.1))/100 -> 8462.4 | AB4: =(SUM(E4,F4)/(M4+0.1))/100 -> 8462.4 | AC4: =(SUM(E4,F4)/(N4+0.1))/100 -> 8462.4 | AD4: =(SUM(E4,F4)/(O4+0.1))/100 -> 8462.4
A5: =A4+1 -> 4 | B5: Atracción Turística | C5: Setas de Sevilla | D5: TripAdvisor | E5: 105610 | F5: 11354 | G5: 4.4 | H5: 4 | I5: =((G5*E5)+(H5*F5))/SUM(E5,F5) -> 4.361171 | J5: =IF(K5>0,1,0) -> 1 | K5: 5 | L5: 150 | M5: 0 | N5: 0 | O5: =(L5*0.5)+(M5*0.4)+(N5*0.1) -> 75 | P5: 793 | Q5: =ABS(G5-H5) -> 0.4 | R5: =ABS(G5-I5) -> 0.038829041 | S5: =ABS(H5-I5) -> 0.36117096 | T5: =SUM(E5,F5)/P5 -> 147.49559 | U5: =LOG10(E5+F5)*I5 -> 22.102642 | V5: =(L5/P5)*100 -> 18.915511 | W5: =(M5/P5)*100 -> 0 | X5: =(N5/P5)*100 -> 0 | Y5: =(O5/P5)*100 -> 9.4577554 | Z5: =E5/F5 -> 9.3015677 | AA5: =(SUM(E5,F5)/(L5+0.1))/100 -> 7.7924051 | AB5: =(SUM(E5,F5)/(M5+0.1))/100 -> 11696.4 | AC5: =(SUM(E5,F5)/(N5+0.1))/100 -> 11696.4 | AD5: =(SUM(E5,F5)/(O5+0.1))/100 -> 15.574434
A6: =A5+1 -> 5 | B6: Atracción Turística | C6: Parque de María Luisa | D6: TripAdvisor | E6: 41265 | F6: 7162 | G6: 4.8 | H6: 4.5 | I6: =((G6*E6)+(H6*F6))/SUM(E6,F6) -> 4.7556322 | J6: =IF(K6>0,1,0) -> 1 | K6: 6 | L6: 1500 | M6: 0 | N6: 0 | O6: =(L6*0.5)+(M6*0.4)+(N6*0.1) -> 750 | P6: 1450 | Q6: =ABS(G6-H6) -> 0.3 | R6: =ABS(G6-I6) -> 0.044367811 | S6: =ABS(H6-I6) -> 0.25563219 | T6: =SUM(E6,F6)/P6 -> 33.397931 | U6: =LOG10(E6+F6)*I6 -> 22.280553 | V6: =(L6/P6)*100 -> 103.44828 | W6: =(M6/P6)*100 -> 0 | X6: =(N6/P6)*100 -> 0 | Y6: =(O6/P6)*100 -> 51.724138 | Z6: =E6/F6 -> 5.7616588 | AA6: =(SUM(E6,F6)/(L6+0.1))/100 -> 0.32282514 | AB6: =(SUM(E6,F6)/(M6+0.1))/100 -> 4842.7 | AC6: =(SUM(E6,F6)/(N6+0.1))/100 -> 4842.7 | AD6: =(SUM(E6,F6)/(O6+0.1))/100 -> 0.64560725
A7: =A6+1 -> 6 | B7: Atracción Turística | C7: La Giralda (Punto 0) | D7: TripAdvisor | E7: 55912 | F7: 11034 | G7: 4.7 | H7: 4.6 | I7: =((G7*E7)+(H7*F7))/SUM(E7,F7) -> 4.6835181 | J7: =IF(K7>0,1,0) -> 1 | K7: 7 | L7: 0 | M7: 1683 | N7: 100 | O7: =(L7*0.5)+(M7*0.4)+(N7*0.1) -> 683.2 | P7: 0.01 | Q7: =ABS(G7-H7) -> 0.1 | R7: =ABS(G7-I7) -> 0.016481941 | S7: =ABS(H7-I7) -> 0.083518059 | T7: =SUM(E7,F7)/P7 -> 6694600 | U7: =LOG10(E7+F7)*I7 -> 22.601368 | V7: =(L7/P7)*100 -> 0 | W7: =(M7/P7)*100 -> 16830000 | X7: =(N7/P7)*100 -> 1000000 | Y7: =(O7/P7)*100 -> 6832000 | Z7: =E7/F7 -> 5.0672467 | AA7: =(SUM(E7,F7)/(L7+0.1))/100 -> 6694.6 | AB7: =(SUM(E7,F7)/(M7+0.1))/100 -> 0.39775414 | AC7: =(SUM(E7,F7)/(N7+0.1))/100 -> 6.6879121 | AD7: =(SUM(E7,F7)/(O7+0.1))/100 -> 0.97974535
A8: =A7+1 -> 7 | B8: Atracción Turística | C8: Casa de Pilatos | D8: TripAdvisor | E8: 13802 | F8: 3929 | G8: 4.4 | H8: 4.3 | I8: =((G8*E8)+(H8*F8))/SUM(E8,F8) -> 4.3778411 | J8: =IF(K8>0,1,0) -> 1 | K8: 8 | L8: 0 | M8: 0 | N8: 0 | O8: =(L8*0.5)+(M8*0.4)+(N8*0.1) -> 0 | P8: 641 | Q8: =ABS(G8-H8) -> 0.1 | R8: =ABS(G8-I8) -> 0.022158931 | S8: =ABS(H8-I8) -> 0.077841069 | T8: =SUM(E8,F8)/P8 -> 27.661466 | U8: =LOG10(E8+F8)*I8 -> 18.600279 | V8: =(L8/P8)*100 -> 0 | W8: =(M8/P8)*100 -> 0 | X8: =(N8/P8)*100 -> 0 | Y8: =(O8/P8)*100 -> 0 | Z8: =E8/F8 -> 3.5128531 | AA8: =(SUM(E8,F8)/(L8+0.1))/100 -> 1773.1 | AB8: =(SUM(E8,F8)/(M8+0.1))/100 -> 1773.1 | AC8: =(SUM(E8,F8)/(N8+0.1))/100 -> 1773.1 | AD8: =(SUM(E8,F8)/(O8+0.1))/100 -> 1773.1
A9: =A8+1 -> 8 | B9: Atracción Turística | C9: Mercado de Triana | D9: TripAdvisor | E9: 10654 | F9: 1132 | G9: 4.4 | H9: 4 | I9: =((G9*E9)+(H9*F9))/SUM(E9,F9) -> 4.3615815 | J9: =IF(K9>0,1,0) -> 1 | K9: 11 | L9: 0 | M9: 0 | N9: 0 | O9: =(L9*0.5)+(M9*0.4)+(N9*0.1) -> 0 | P9: 974 | Q9: =ABS(G9-H9) -> 0.4 | R9: =ABS(G9-I9) -> 0.038418463 | S9: =ABS(H9-I9) -> 0.36158154 | T9: =SUM(E9,F9)/P9 -> 12.100616 | U9: =LOG10(E9+F9)*I9 -> 17.757597 | V9: =(L9/P9)*100 -> 0 | W9: =(M9/P9)*100 -> 0 | X9: =(N9/P9)*100 -> 0 | Y9: =(O9/P9)*100 -> 0 | Z9: =E9/F9 -> 9.4116608 | AA9: =(SUM(E9,F9)/(L9+0.1))/100 -> 1178.6 | AB9: =(SUM(E9,F9)/(M9+0.1))/100 -> 1178.6 | AC9: =(SUM(E9,F9)/(N9+0.1))/100 -> 1178.6 | AD9: =(SUM(E9,F9)/(O9+0.1))/100 -> 1178.6
A10: =A9+1 -> 9 | B10: Atracción Turística | C10: Museo de Bellas Artes | D10: TripAdvisor | E10: 16014 | F10: 2218 | G10: 4.7 | H10: 4.4 | I10: =((G10*E10)+(H10*F10))/SUM(E10,F10) -> 4.6635037 | J10: =IF(K10>0,1,0) -> 1 | K10: 12 | L10: 0 | M10: 0 | N10: 0 | O10: =(L10*0.5)+(M10*0.4)+(N10*0.1) -> 0 | P10: 962 | Q10: =ABS(G10-H10) -> 0.3 | R10: =ABS(G10-I10) -> 0.03649627 | S10: =ABS(H10-I10) -> 0.26350373 | T10: =SUM(E10,F10)/P10 -> 18.952183 | U10: =LOG10(E10+F10)*I10 -> 19.870417 | V10: =(L10/P10)*100 -> 0 | W10: =(M10/P10)*100 -> 0 | X10: =(N10/P10)*100 -> 0 | Y10: =(O10/P10)*100 -> 0 | Z10: =E10/F10 -> 7.220018 | AA10: =(SUM(E10,F10)/(L10+0.1))/100 -> 1823.2 | AB10: =(SUM(E10,F10)/(M10+0.1))/100 -> 1823.2 | AC10: =(SUM(E10,F10)/(N10+0.1))/100 -> 1823.2 | AD10: =(SUM(E10,F10)/(O10+0.1))/100 -> 1823.2
A11: =A10+1 -> 10 | B11: Atracción Turística | C11: Real Maestranza de Caballería | D11: TripAdvisor | E11: 31701 | F11: 5718 | G11: 4.4 | H11: 4.1 | I11: =((G11*E11)+(H11*F11))/SUM(E11,F11) -> 4.354157 | J11: =IF(K11>0,1,0) -> 1 | K11: 13 | L11: 0 | M11: 0 | N11: 0 | O11: =(L11*0.5)+(M11*0.4)+(N11*0.1) -> 0 | P11: 553 | Q11: =ABS(G11-H11) -> 0.3 | R11: =ABS(G11-I11) -> 0.045843021 | S11: =ABS(H11-I11) -> 0.25415698 | T11: =SUM(E11,F11)/P11 -> 67.665461 | U11: =LOG10(E11+F11)*I11 -> 19.911961 | V11: =(L11/P11)*100 -> 0 | W11: =(M11/P11)*100 -> 0 | X11: =(N11/P11)*100 -> 0 | Y11: =(O11/P11)*100 -> 0 | Z11: =E11/F11 -> 5.5440714 | AA11: =(SUM(E11,F11)/(L11+0.1))/100 -> 3741.9 | AB11: =(SUM(E11,F11)/(M11+0.1))/100 -> 3741.9 | AC11: =(SUM(E11,F11)/(N11+0.1))/100 -> 3741.9 | AD11: =(SUM(E11,F11)/(O11+0.1))/100 -> 3741.9
A12: =A11+1 -> 11 | B12: Atracción Turística | C12: Basílica de la Macarena | D12: TripAdvisor | E12: 3506 | F12: 2484 | G12: 4.8 | H12: 4.4 | I12: =((G12*E12)+(H12*F12))/SUM(E12,F12) -> 4.6341235 | J12: =IF(K12>0,1,0) -> 1 | K12: 14 | L12: 0 | M12: 0 | N12: 0 | O12: =(L12*0.5)+(M12*0.4)+(N12*0.1) -> 0 | P12: 1850 | Q12: =ABS(G12-H12) -> 0.4 | R12: =ABS(G12-I12) -> 0.16587646 | S12: =ABS(H12-I12) -> 0.23412354 | T12: =SUM(E12,F12)/P12 -> 3.2378378 | U12: =LOG10(E12+F12)*I12 -> 17.505063 | V12: =(L12/P12)*100 -> 0 | W12: =(M12/P12)*100 -> 0 | X12: =(N12/P12)*100 -> 0 | Y12: =(O12/P12)*100 -> 0 | Z12: =E12/F12 -> 1.4114332 | AA12: =(SUM(E12,F12)/(L12+0.1))/100 -> 599 | AB12: =(SUM(E12,F12)/(M12+0.1))/100 -> 599 | AC12: =(SUM(E12,F12)/(N12+0.1))/100 -> 599 | AD12: =(SUM(E12,F12)/(O12+0.1))/100 -> 599
A13: =A12+1 -> 12 | B13: Atracción Turística | C13: Isla Mágica | D13: TripAdvisor | E13: 32790 | F13: 2730 | G13: 4.1 | H13: 3.6 | I13: =((G13*E13)+(H13*F13))/SUM(E13,F13) -> 4.0615709 | J13: =IF(K13>0,1,0) -> 1 | K13: 15 | L13: 8 | M13: 0 | N13: 0 | O13: =(L13*0.5)+(M13*0.4)+(N13*0.1) -> 4 | P13: 2260 | Q13: =ABS(G13-H13) -> 0.5 | R13: =ABS(G13-I13) -> 0.038429054 | S13: =ABS(H13-I13) -> 0.46157095 | T13: =SUM(E13,F13)/P13 -> 15.716814 | U13: =LOG10(E13+F13)*I13 -> 18.482069 | V13: =(L13/P13)*100 -> 0.3539823 | W13: =(M13/P13)*100 -> 0 | X13: =(N13/P13)*100 -> 0 | Y13: =(O13/P13)*100 -> 0.17699115 | Z13: =E13/F13 -> 12.010989 | AA13: =(SUM(E13,F13)/(L13+0.1))/100 -> 43.851852 | AB13: =(SUM(E13,F13)/(M13+0.1))/100 -> 3552 | AC13: =(SUM(E13,F13)/(N13+0.1))/100 -> 3552 | AD13: =(SUM(E13,F13)/(O13+0.1))/100 -> 86.634146
A14: =A13+1 -> 13 | B14: Atracción Turística | C14: Museo de las Ilusiones de Sevilla | D14: TripAdvisor | E14: 4771 | F14: 527 | G14: 4.5 | H14: 4.7 | I14: =((G14*E14)+(H14*F14))/SUM(E14,F14) -> 4.5198943 | J14: =IF(K14>0,1,0) -> 1 | K14: 16 | L14: 0 | M14: 0 | N14: 0 | O14: =(L14*0.5)+(M14*0.4)+(N14*0.1) -> 0 | P14: 743 | Q14: =ABS(G14-H14) -> 0.2 | R14: =ABS(G14-I14) -> 0.0198943 | S14: =ABS(H14-I14) -> 0.1801057 | T14: =SUM(E14,F14)/P14 -> 7.1305518 | U14: =LOG10(E14+F14)*I14 -> 16.832592 | V14: =(L14/P14)*100 -> 0 | W14: =(M14/P14)*100 -> 0 | X14: =(N14/P14)*100 -> 0 | Y14: =(O14/P14)*100 -> 0 | Z14: =E14/F14 -> 9.0531309 | AA14: =(SUM(E14,F14)/(L14+0.1))/100 -> 529.8 | AB14: =(SUM(E14,F14)/(M14+0.1))/100 -> 529.8 | AC14: =(SUM(E14,F14)/(N14+0.1))/100 -> 529.8 | AD14: =(SUM(E14,F14)/(O14+0.1))/100 -> 529.8
... A26: =A25+1 -> 25 | B26: Atracción Turística | C26: Torre del Oro | D26: TripAdvisor | E26: 53575 | F26: 2469 | G26: 4.5 | H26: 3.9 | I26: =((G26*E26)+(H26*F26))/SUM(E26,F26) -> 4.4735672 | J26: =IF(K26>0,1,0) -> 1 | K26: 33 | L26: 0 | M26: 0 | N26: 0 | O26: =(L26*0.5)+(M26*0.4)+(N26*0.1) -> 0 | P26: 522 | Q26: =ABS(G26-H26) -> 0.6 | R26: =ABS(G26-I26) -> 0.026432803 | S26: =ABS(H26-I26) -> 0.5735672 | T26: =SUM(E26,F26)/P26 -> 107.36398 | U26: =LOG10(E26+F26)*I26 -> 21.242864 | V26: =(L26/P26)*100 -> 0 | W26: =(M26/P26)*100 -> 0 | X26: =(N26/P26)*100 -> 0 | Y26: =(O26/P26)*100 -> 0 | Z26: =E26/F26 -> 21.699068 | AA26: =(SUM(E26,F26)/(L26+0.1))/100 -> 5604.4 | AB26: =(SUM(E26,F26)/(M26+0.1))/100 -> 5604.4 | AC26: =(SUM(E26,F26)/(N26+0.1))/100 -> 5604.4 | AD26: =(SUM(E26,F26)/(O26+0.1))/100 -> 5604.4
A27: =A26+1 -> 26 | B27: Atracción Turística | C27: Parque de los Descubrimientos | D27: Intruso | E27: 1503 | F27: 1 | G27: 4.3 | H27: 0 | I27: =((G27*E27)+(H27*F27))/SUM(E27,F27) -> 4.297141 | J27: =IF(K27>0,1,0) -> 0 | K27: 0 | L27: 806 | M27: 0 | N27: 0 | O27: =(L27*0.5)+(M27*0.4)+(N27*0.1) -> 403 | P27: 1540 | Q27: =ABS(G27-H27) -> 4.3 | R27: =ABS(H27-I27) -> 4.297141 | S27: =ABS(H27-I27) -> 4.297141 | T27: =SUM(E27,F27)/P27 -> 0.97662338 | U27: =LOG10(E27+F27)*I27 -> 13.653082 | V27: =(L27/P27)*100 -> 52.337662 | W27: =(M27/P27)*100 -> 0 | X27: =(N27/P27)*100 -> 0 | Y27: =(O27/P27)*100 -> 26.168831 | Z27: =E27/F27 -> 1503 | AA27: =(SUM(E27,F27)/(L27+0.1))/100 -> 0.018657735 | AB27: =(SUM(E27,F27)/(M27+0.1))/100 -> 150.4 | AC27: =(SUM(E27,F27)/(N27+0.1))/100 -> 150.4 | AD27: =(SUM(E27,F27)/(O27+0.1))/100 -> 0.037310841
A28: =A27+1 -> 27 | B28: Atracción Turística | C28: Estanque Central de Plaza de América | D28: Intruso | E28: 52 | F28: 657 | G28: 4.8 | H28: 4.4 | I28: =((G28*E28)+(H28*F28))/SUM(E28,F28) -> 4.4293371 | J28: =IF(K28>0,1,0) -> 1 | K28: 40 | L28: 537 | M28: 93 | N28: 0 | O28: =(L28*0.5)+(M28*0.4)+(N28*0.1) -> 305.7 | P28: 1700 | Q28: =ABS(G28-H28) -> 0.4 | R28: =ABS(H28-I28) -> 0.029337094 | S28: =ABS(H28-I28) -> 0.029337094 | T28: =SUM(E28,F28)/P28 -> 0.41705882 | U28: =LOG10(E28+F28)*I28 -> 12.626473 | V28: =(L28/P28)*100 -> 31.588235 | W28: =(M28/P28)*100 -> 5.4705882 | X28: =(N28/P28)*100 -> 0 | Y28: =(O28/P28)*100 -> 17.982353 | Z28: =E28/F28 -> 0.079147641 | AA28: =(SUM(E28,F28)/(L28+0.1))/100 -> 0.013200521 | AB28: =(SUM(E28,F28)/(M28+0.1))/100 -> 0.076154672 | AC28: =(SUM(E28,F28)/(N28+0.1))/100 -> 70.9 | AD28: =(SUM(E28,F28)/(O28+0.1))/100 -> 0.023185088
A29: =A28+1 -> 28 | B29: Atracción Turística | C29: Torre Sur | D29: Intruso | E29: 165 | F29: 3 | G29: 4.8 | H29: 4.3 | I29: =((G29*E29)+(H29*F29))/SUM(E29,F29) -> 4.7910714 | J29: =IF(K29>0,1,0) -> 1 | K29: 254 | L29: 347 | M29: 0 | N29: 0 | O29: =(L29*0.5)+(M29*0.4)+(N29*0.1) -> 173.5 | P29: 1250 | Q29: =ABS(G29-H29) -> 0.5 | R29: =ABS(H29-I29) -> 0.49107143 | S29: =ABS(H29-I29) -> 0.49107143 | T29: =SUM(E29,F29)/P29 -> 0.1344 | U29: =LOG10(E29+F29)*I29 -> 10.661616 | V29: =(L29/P29)*100 -> 27.76 | W29: =(M29/P29)*100 -> 0 | X29: =(N29/P29)*100 -> 0 | Y29: =(O29/P29)*100 -> 13.88 | Z29: =E29/F29 -> 55 | AA29: =(SUM(E29,F29)/(L29+0.1))/100 -> 0.0048401037 | AB29: =(SUM(E29,F29)/(M29+0.1))/100 -> 16.8 | AC29: =(SUM(E29,F29)/(N29+0.1))/100 -> 16.8 | AD29: =(SUM(E29,F29)/(O29+0.1))/100 -> 0.0096774194
A30: =A29+1 -> 29 | B30: Atracción Turística | C30: Mosaico Guadalquivir | D30: Intruso | E30: 21 | F30: 1 | G30: 4.5 | H30: 0 | I30: =((G30*E30)+(H30*F30))/SUM(E30,F30) -> 4.2954545 | J30: =IF(K30>0,1,0) -> 0 | K30: 0 | L30: 182 | M30: 0 | N30: 0 | O30: =(L30*0.5)+(M30*0.4)+(N30*0.1) -> 91 | P30: 864 | Q30: =ABS(G30-H30) -> 4.5 | R30: =ABS(H30-I30) -> 4.2954545 | S30: =ABS(H30-I30) -> 4.2954545 | T30: =SUM(E30,F30)/P30 -> 0.025462963 | U30: =LOG10(E30+F30)*I30 -> 5.7663156 | V30: =(L30/P30)*100 -> 21.064815 | W30: =(M30/P30)*100 -> 0 | X30: =(N30/P30)*100 -> 0 | Y30: =(O30/P30)*100 -> 10.532407 | Z30: =E30/F30 -> 21 | AA30: =(SUM(E30,F30)/(L30+0.1))/100 -> 0.0012081274 | AB30: =(SUM(E30,F30)/(M30+0.1))/100 -> 2.2 | AC30: =(SUM(E30,F30)/(N30+0.1))/100 -> 2.2 | AD30: =(SUM(E30,F30)/(O30+0.1))/100 -> 0.0024149286
A31: =A30+1 -> 30 | B31: Atracción Turística | C31: Fuente de las Cuatro Estaciones | D31: Intruso | E31: 46 | F31: 17 | G31: 4.7 | H31: 3.7 | I31: =((G31*E31)+(H31*F31))/SUM(E31,F31) -> 4.4301587 | J31: =IF(K31>0,1,0) -> 1 | K31: 187 | L31: 13 | M31: 390 | N31: 0 | O31: =(L31*0.5)+(M31*0.4)+(N31*0.1) -> 162.5 | P31: 671 | Q31: =ABS(G31-H31) -> 1 | R31: =ABS(H31-I31) -> 0.73015873 | S31: =ABS(H31-I31) -> 0.73015873 | T31: =SUM(E31,F31)/P31 -> 0.093889717 | U31: =LOG10(E31+F31)*I31 -> 7.9713642 | V31: =(L31/P31)*100 -> 1.9374069 | W31: =(M31/P31)*100 -> 58.122206 | X31: =(N31/P31)*100 -> 0 | Y31: =(O31/P31)*100 -> 24.217586 | Z31: =E31/F31 -> 2.7058824 | AA31: =(SUM(E31,F31)/(L31+0.1))/100 -> 0.048091603 | AB31: =(SUM(E31,F31)/(M31+0.1))/100 -> 0.0016149705 | AC31: =(SUM(E31,F31)/(N31+0.1))/100 -> 6.3 | AD31: =(SUM(E31,F31)/(O31+0.1))/100 -> 0.0038745387
A32: =A31+1 -> 31 | B32: Atracción Turística | C32: Reja del Diablo | D32: Intruso | E32: 64 | F32: 1 | G32: 4.5 | H32: 0 | I32: =((G32*E32)+(H32*F32))/SUM(E32,F32) -> 4.4307692 | J32: =IF(K32>0,1,0) -> 0 | K32: 0 | L32: 0 | M32: 272 | N32: 50 | O32: =(L32*0.5)+(M32*0.4)+(N32*0.1) -> 113.8 | P32: 363 | Q32: =ABS(G32-H32) -> 4.5 | R32: =ABS(H32-I32) -> 4.4307692 | S32: =ABS(H32-I32) -> 4.4307692 | T32: =SUM(E32,F32)/P32 -> 0.17906336 | U32: =LOG10(E32+F32)*I32 -> 8.0326007 | V32: =(L32/P32)*100 -> 0 | W32: =(M32/P32)*100 -> 74.931129 | X32: =(N32/P32)*100 -> 13.774105 | Y32: =(O32/P32)*100 -> 31.349862 | Z32: =E32/F32 -> 64 | AA32: =(SUM(E32,F32)/(L32+0.1))/100 -> 6.5 | AB32: =(SUM(E32,F32)/(M32+0.1))/100 -> 0.0023888276 | AC32: =(SUM(E32,F32)/(N32+0.1))/100 -> 0.012974052 | AD32: =(SUM(E32,F32)/(O32+0.1))/100 -> 0.0057067603
A33: =A32+1 -> 32 | B33: Atracción Turística | C33: Monte Gurugú | D33: Intruso | E33: 388 | F33: 1 | G33: 4.4 | H33: 5 | I33: =((G33*E33)+(H33*F33))/SUM(E33,F33) -> 4.4015424 | J33: =IF(K33>0,1,0) -> 1 | K33: 355 | L33: 0 | M33: 183 | N33: 133 | O33: =(L33*0.5)+(M33*0.4)+(N33*0.1) -> 86.5 | P33: 1520 | Q33: =ABS(G33-H33) -> 0.6 | R33: =ABS(H33-I33) -> 0.59845758 | S33: =ABS(H33-I33) -> 0.59845758 | T33: =SUM(E33,F33)/P33 -> 0.25592105 | U33: =LOG10(E33+F33)*I33 -> 11.399773 | V33: =(L33/P33)*100 -> 0 | W33: =(M33/P33)*100 -> 12.039474 | X33: =(N33/P33)*100 -> 8.75 | Y33: =(O33/P33)*100 -> 5.6907895 | Z33: =E33/F33 -> 388 | AA33: =(SUM(E33,F33)/(L33+0.1))/100 -> 38.9 | AB33: =(SUM(E33,F33)/(M33+0.1))/100 -> 0.021245221 | AC33: =(SUM(E33,F33)/(N33+0.1))/100 -> 0.029226146 | AD33: =(SUM(E33,F33)/(O33+0.1))/100 -> 0.044919169
A34: =A33+1 -> 33 | B34: Atracción Turística | C34: Arco de la Macarena | D34: Intruso | E34: 4300 | F34: 42 | G34: 4.5 | H34: 3.8 | I34: =((G34*E34)+(H34*F34))/SUM(E34,F34) -> 4.4932289 | J34: =IF(K34>0,1,0) -> 1 | K34: 107 | L34: 33 | M34: 163 | N34: 150 | O34: =(L34*0.5)+(M34*0.4)+(N34*0.1) -> 96.7 | P34: 1870 | Q34: =ABS(G34-H34) -> 0.7 | R34: =ABS(H34-I34) -> 0.69322893 | S34: =ABS(H34-I34) -> 0.69322893 | T34: =SUM(E34,F34)/P34 -> 2.3219251 | U34: =LOG10(E34+F34)*I34 -> 16.344973 | V34: =(L34/P34)*100 -> 1.7647059 | W34: =(M34/P34)*100 -> 8.7165775 | X34: =(N34/P34)*100 -> 8.0213904 | Y34: =(O34/P34)*100 -> 5.171123 | Z34: =E34/F34 -> 102.38095 | AA34: =(SUM(E34,F34)/(L34+0.1))/100 -> 1.3117825 | AB34: =(SUM(E34,F34)/(M34+0.1))/100 -> 0.26621704 | AC34: =(SUM(E34,F34)/(N34+0.1))/100 -> 0.28927382 | AD34: =(SUM(E34,F34)/(O34+0.1))/100 -> 0.44855372
A35: =A34+1 -> 34 | B35: Atracción Turística | C35: Mural "De Viaje" de Cn6 | D35: Intruso | E35: 1 | F35: 1 | G35: 1 | H35: 0 | I35: =((G35*E35)+(H35*F35))/SUM(E35,F35) -> 0.5 | J35: =IF(K35>0,1,0) -> 0 | K35: 0 | L35: 0 | M35: 140 | N35: 0 | O35: =(L35*0.5)+(M35*0.4)+(N35*0.1) -> 56 | P35: 1140 | Q35: =ABS(G35-H35) -> 1 | R35: =ABS(H35-I35) -> 0.5 | S35: =ABS(H35-I35) -> 0.5 | T35: =SUM(E35,F35)/P35 -> 0.001754386 | U35: =LOG10(E35+F35)*I35 -> 0.150515 | V35: =(L35/P35)*100 -> 0 | W35: =(M35/P35)*100 -> 12.280702 | X35: =(N35/P35)*100 -> 0 | Y35: =(O35/P35)*100 -> 4.9122807 | Z35: =E35/F35 -> 1 | AA35: =(SUM(E35,F35)/(L35+0.1))/100 -> 0.2 | AB35: =(SUM(E35,F35)/(M35+0.1))/100 -> 0.00014275517 | AC35: =(SUM(E35,F35)/(N35+0.1))/100 -> 0.2 | AD35: =(SUM(E35,F35)/(O35+0.1))/100 -> 0.00035650624
A36: =A35+1 -> 35 | B36: Atracción Turística | C36: Mural "De Viaje" de Kato | D36: Intruso | E36: 0 | F36: 1 | G36: 0 | H36: 0 | I36: 0 | J36: =IF(K36>0,1,0) -> 0 | K36: 0 | L36: 0 | M36: 112 | N36: 25 | O36: =(L36*0.5)+(M36*0.4)+(N36*0.1) -> 47.3 | P36: 1560 | Q36: =ABS(G36-H36) -> 0 | R36: =ABS(H36-I36) -> 0 | S36: =ABS(H36-I36) -> 0 | T36: =SUM(E36,F36)/P36 -> 0.00064102564 | U36: 0 | V36: =(L36/P36)*100 -> 0 | W36: =(M36/P36)*100 -> 7.1794872 | X36: =(N36/P36)*100 -> 1.6025641 | Y36: =(O36/P36)*100 -> 3.0320513 | Z36: =E36/F36 -> 0 | AA36: =(SUM(E36,F36)/(L36+0.1))/100 -> 0.1 | AB36: =(SUM(E36,F36)/(M36+0.1))/100 -> 8.9206066e-05 | AC36: =(SUM(E36,F36)/(N36+0.1))/100 -> 0.00039840637 | AD36: =(SUM(E36,F36)/(O36+0.1))/100 -> 0.00021097046

Sheet h1
A1: id | B1: categoria | C1: recurso | D1: origen | E1: v1a | F1: v1b | G1: v2a | H1: v2b | I1: v2p | J1: v3con | K1: v3 | L1: v4a | M1: v4b | N1: v4c | O1: v4p | P1: v5 | Q1: v6a | R1: v6b | S1: v6c | T1: v7 | U1: v8 | V1: v9a | W1: v9b | X1: v9c | Y1: v9p | Z1: v10 | AA1: v11a | AB1: v11b | AC1: v11c | AD1: v11p
A2: ='Atracciones Turísticas Completo'!A2 -> 1 | B2: ='Atracciones Turísticas Completo'!B2 -> Atracción Turística | C2: ='Atracciones Turísticas Completo'!C2 -> Plaza de España | D2: ='Atracciones Turísticas Completo'!D2 -> TripAdvisor | E2: ='Atracciones Turísticas Completo'!E2 -> 181284 | F2: ='Atracciones Turísticas Completo'!F2 -> 45480 | G2: ='Atracciones Turísticas Completo'!G2 -> 4.8 | H2: ='Atracciones Turísticas Completo'!H2 -> 4.8 | ... AD2: ='Atracciones Turísticas Completo'!AD2 -> 22676.4
A3: ='Atracciones Turísticas Completo'!A3 -> 2 | B3: ='Atracciones Turísticas Completo'!B3 -> Atracción Turística | C3: ='Atracciones Turísticas Completo'!C3 -> Real Alcázar de Sevilla | D3: ='Atracciones Turísticas Completo'!D3 -> TripAdvisor | E3: ='Atracciones Turísticas Completo'!E3 -> 98150 | F3: ='Atracciones Turísticas Completo'!F3 -> 36806 | G3: ='Atracciones Turísticas Completo'!G3 -> 4.7 | H3: ='Atracciones Turísticas Completo'!H3 -> 4.7 | ... AD3: ='Atracciones Turísticas Completo'!AD3 -> 13495.6
A4: ='Atracciones Turísticas Completo'!A4 -> 3 | B4: ='Atracciones Turísticas Completo'!B4 -> Atracción Turística | C4: ='Atracciones Turísticas Completo'!C4 -> Catedral de Sevilla | D4: ='Atracciones Turísticas Completo'!D4 -> TripAdvisor | E4: ='Atracciones Turísticas Completo'!E4 -> 57330 | F4: ='Atracciones Turísticas Completo'!F4 -> 27294 | G4: ='Atracciones Turísticas Completo'!G4 -> 4.8 | H4: ='Atracciones Turísticas Completo'!H4 -> 4.6 | ... AD4: ='Atracciones Turísticas Completo'!AD4 -> 8462.4
A5: ='Atracciones Turísticas Completo'!A5 -> 4 | B5: ='Atracciones Turísticas Completo'!B5 -> Atracción Turística | C5: ='Atracciones Turísticas Completo'!C5 -> Setas de Sevilla | D5: ='Atracciones Turísticas Completo'!D5 -> TripAdvisor | E5: ='Atracciones Turísticas Completo'!E5 -> 105610 | F5: ='Atracciones Turísticas Completo'!F5 -> 11354 | G5: ='Atracciones Turísticas Completo'!G5 -> 4.4 | H5: ='Atracciones Turísticas Completo'!H5 -> 4 | ... AD5: ='Atracciones Turísticas Completo'!AD5 -> 15.574434
A6: ='Atracciones Turísticas Completo'!A6 -> 5 | B6: ='Atracciones Turísticas Completo'!B6 -> Atracción Turística | C6: ='Atracciones Turísticas Completo'!C6 -> Parque de María Luisa | D6: ='Atracciones Turísticas Completo'!D6 -> TripAdvisor | E6: ='Atracciones Turísticas Completo'!E6 -> 41265 | F6: ='Atracciones Turísticas Completo'!F6 -> 7162 | G6: ='Atracciones Turísticas Completo'!G6 -> 4.8 | H6: ='Atracciones Turísticas Completo'!H6 -> 4.5 | ... AD6: ='Atracciones Turísticas Completo'!AD6 -> 0.64560725
A7: ='Atracciones Turísticas Completo'!A7 -> 6 | B7: ='Atracciones Turísticas Completo'!B7 -> Atracción Turística | C7: ='Atracciones Turísticas Completo'!C7 -> La Giralda (Punto 0) | D7: ='Atracciones Turísticas Completo'!D7 -> TripAdvisor | E7: ='Atracciones Turísticas Completo'!E7 -> 55912 | F7: ='Atracciones Turísticas Completo'!F7 -> 11034 | G7: ='Atracciones Turísticas Completo'!G7 -> 4.7 | H7: ='Atracciones Turísticas Completo'!H7 -> 4.6 | ... AD7: ='Atracciones Turísticas Completo'!AD7 -> 0.97974535
A8: ='Atracciones Turísticas Completo'!A8 -> 7 | B8: ='Atracciones Turísticas Completo'!B8 -> Atracción Turística | C8: ='Atracciones Turísticas Completo'!C8 -> Casa de Pilatos | D8: ='Atracciones Turísticas Completo'!D8 -> TripAdvisor | E8: ='Atracciones Turísticas Completo'!E8 -> 13802 | F8: ='Atracciones Turísticas Completo'!F8 -> 3929 | G8: ='Atracciones Turísticas Completo'!G8 -> 4.4 | H8: ='Atracciones Turísticas Completo'!H8 -> 4.3 | ... AD8: ='Atracciones Turísticas Completo'!AD8 -> 1773.1
A9: ='Atracciones Turísticas Completo'!A9 -> 8 | B9: ='Atracciones Turísticas Completo'!B9 -> Atracción Turística | C9: ='Atracciones Turísticas Completo'!C9 -> Mercado de Triana | D9: ='Atracciones Turísticas Completo'!D9 -> TripAdvisor | E9: ='Atracciones Turísticas Completo'!E9 -> 10654 | F9: ='Atracciones Turísticas Completo'!F9 -> 1132 | G9: ='Atracciones Turísticas Completo'!G9 -> 4.4 | H9: ='Atracciones Turísticas Completo'!H9 -> 4 | ... AD9: ='Atracciones Turísticas Completo'!AD9 -> 1178.6
A10: ='Atracciones Turísticas Completo'!A10 -> 9 | B10: ='Atracciones Turísticas Completo'!B10 -> Atracción Turística | C10: ='Atracciones Turísticas Completo'!C10 -> Museo de Bellas Artes | D10: ='Atracciones Turísticas Completo'!D10 -> TripAdvisor | E10: ='Atracciones Turísticas Completo'!E10 -> 16014 | F10: ='Atracciones Turísticas Completo'!F10 -> 2218 | G10: ='Atracciones Turísticas Completo'!G10 -> 4.7 | H10: ='Atracciones Turísticas Completo'!H10 -> 4.4 | ... AD10: ='Atracciones Turísticas Completo'!AD10 -> 1823.2
A11: ='Atracciones Turísticas Completo'!A11 -> 10 | B11: ='Atracciones Turísticas Completo'!B11 -> Atracción Turística | C11: ='Atracciones Turísticas Completo'!C11 -> Real Maestranza de Caballería | D11: ='Atracciones Turísticas Completo'!D11 -> TripAdvisor | E11: ='Atracciones Turísticas Completo'!E11 -> 31701 | F11: ='Atracciones Turísticas Completo'!F11 -> 5718 | G11: ='Atracciones Turísticas Completo'!G11 -> 4.4 | H11: ='Atracciones Turísticas Completo'!H11 -> 4.1 | ... AD11: ='Atracciones Turísticas Completo'!AD11 -> 3741.9
A12: ='Atracciones Turísticas Completo'!A12 -> 11 | B12: ='Atracciones Turísticas Completo'!B12 -> Atracción Turística | C12: ='Atracciones Turísticas Completo'!C12 -> Basílica de la Macarena | D12: ='Atracciones Turísticas Completo'!D12 -> TripAdvisor | E12: ='Atracciones Turísticas Completo'!E12 -> 3506 | F12: ='Atracciones Turísticas Completo'!F12 -> 2484 | G12: ='Atracciones Turísticas Completo'!G12 -> 4.8 | H12: ='Atracciones Turísticas Completo'!H12 -> 4.4 | ... AD12: ='Atracciones Turísticas Completo'!AD12 -> 599
A13: ='Atracciones Turísticas Completo'!A13 -> 12 | B13: ='Atracciones Turísticas Completo'!B13 -> Atracción Turística | C13: ='Atracciones Turísticas Completo'!C13 -> Isla Mágica | D13: ='Atracciones Turísticas Completo'!D13 -> TripAdvisor | E13: ='Atracciones Turísticas Completo'!E13 -> 32790 | F13: ='Atracciones Turísticas Completo'!F13 -> 2730 | G13: ='Atracciones Turísticas Completo'!G13 -> 4.1 | H13: ='Atracciones Turísticas Completo'!H13 -> 3.6 | ... AD13: ='Atracciones Turísticas Completo'!AD13 -> 86.634146
... A36: ='Atracciones Turísticas Completo'!A36 -> 35 | B36: ='Atracciones Turísticas Completo'!B36 -> Atracción Turística | C36: ='Atracciones Turísticas Completo'!C36 -> Mural "De Viaje" de Kato | D36: ='Atracciones Turísticas Completo'!D36 -> Intruso | E36: ='Atracciones Turísticas Completo'!E36 -> 0 | F36: ='Atracciones Turísticas Completo'!F36 -> 1 | G36: ='Atracciones Turísticas Completo'!G36 -> 0 | H36: ='Atracciones Turísticas Completo'!H36 -> 0 | ... AD36: ='Atracciones Turísticas Completo'!AD36 -> 0.00021097046

Sheet Restauración 2.1 (TripAdvisor)
A1: ID | B1: Categoría del Recurso | C1: Recurso | D1: Origen | E1: V1​a Masa Crítica - Google (Contraste) (Número de Reseñas) | F1: V1​b Masa Crítica - TripAdvisor (Origen) (Número de Reseñas) | G1: V2a​ Calidad - Google (Contraste) (Puntuación 0-5) | H1: V2b​ Calidad - TripAdvisor (Origen) (Puntuación 0-5) | I1: V2 Ponderada | J1: V3​ Ranking - TripAdvisor | K1: V4a​ Grado de Presencia Algorítmica (web) | L1: V4b Grado de Presencia Algorítmica (maps libre) | M1: V4c​ Grado de Presencia Algorítmica (maps forzado) | N1: V4​ Ponderada | O1: V5 Proximidad al Punto 0 (Metros) | P1: V6a Desviación Calidad (Contraste-Origen) | Q1: V6b Desviación de Calidad (Contraste-Ponderada) | R1: V6c Desviación de Calidad (Origen-Ponderada) | S1: V7 Grado de atención turística digital según ubicación | T1: V8 Grado de capital reputacional digital | U1: V9a Grado de Visibilidad Espacial Algorítmica en web | V1: V9b Grado de Visibilidad Espacial Algorítmica en maps libre | W1: V9c Grado de Visibilidad Espacial Algorítmica en maps forzado | X1: V9 Ponderada | Y1: V10 Grado de Ventaja Algorítmica entre Plataformas | Z1: V11a Grado de Presión Turística Digital según web | AA1: V11b Grado de Presión Turística Digital según maps libre | AB1: V11c Grado de Presión Turística Digital según maps forzado | AC1: V11 Ponderada
A2: ='Atracción 1.3 (Intrusos LP)'!A11+1 -> 36 | B2: Restauración | C2: Alimentari E Diversi | D2: Tripadvisor | E2: 2879 | F2: 3339 | G2: 4.7 | H2: 4.9 | I2: =((G2*E2)+(H2*F2))/SUM(E2,F2) -> 4.8073979 | J2: 1 | K2: 0 | L2: 50 | M2: 33 | N2: =(K2*0.5)+(L2*0.4)+(M2*0.1) -> 23.3 | O2: 837 | P2: =ABS(G2-H2) -> 0.2 | Q2: =ABS(H2-I2) -> 0.092602123 | R2: =ABS(H2-I2) -> 0.092602123 | S2: =SUM(E2,F2)/O2 -> 7.4289128 | T2: =LOG10(E2+F2)*I2 -> 18.237588 | U2: =(K2/O2)*100 -> 0 | V2: =(L2/O2)*100 -> 5.9737157 | W2: =(M2/O2)*100 -> 3.9426523 | X2: =(N2/O2)*100 -> 2.7837515 | Y2: =E2/F2 -> 0.8622342 | Z2: =(SUM(E2,F2)/(K2+0.1))/100 -> 621.8 | AA2: =(SUM(E2,F2)/(L2+0.1))/100 -> 1.2411178 | AB2: =(SUM(E2,F2)/(M2+0.1))/100 -> 1.8785498 | AC2: =(SUM(E2,F2)/(N2+0.1))/100 -> 2.657265
A3: =A2+1 -> 37 | B3: Restauración | C3: Fatouch | D3: Tripadvisor | E3: 3302 | F3: 2510 | G3: 4.7 | H3: 4.9 | I3: =((G3*E3)+(H3*F3))/SUM(E3,F3) -> 4.786373 | J3: 2 | K3: 0 | L3: 0 | M3: 0 | N3: =(K3*0.5)+(L3*0.4)+(M3*0.1) -> 0 | O3: 1220 | P3: =ABS(G3-H3) -> 0.2 | Q3: =ABS(G3-I3) -> 0.086373021 | R3: =ABS(H3-I3) -> 0.11362698 | S3: =SUM(E3,F3)/O3 -> 4.7639344 | T3: =LOG10(E3+F3)*I3 -> 18.017467 | U3: =(K3/O3)*100 -> 0 | V3: =(L3/O3)*100 -> 0 | W3: =(M3/O3)*100 -> 0 | X3: =(N3/O3)*100 -> 0 | Y3: =E3/F3 -> 1.3155378 | Z3: =(SUM(E3,F3)/(K3+0.1))/100 -> 581.2 | AA3: =(SUM(E3,F3)/(L3+0.1))/100 -> 581.2 | AB3: =(SUM(E3,F3)/(M3+0.1))/100 -> 581.2 | AC3: =(SUM(E3,F3)/(N3+0.1))/100 -> 581.2
A4: =A3+1 -> 38 | B4: Restauración | C4: Bodega Palo Santo | D4: Tripadvisor | E4: 2726 | F4: 2085 | G4: 4.6 | H4: 4.8 | I4: =((G4*E4)+(H4*F4))/SUM(E4,F4) -> 4.6866764 | J4: 3 | K4: 0 | L4: 0 | M4: 0 | N4: =(K4*0.5)+(L4*0.4)+(M4*0.1) -> 0 | O4: 1060 | P4: =ABS(G4-H4) -> 0.2 | Q4: =ABS(G4-I4) -> 0.086676367 | R4: =ABS(H4-I4) -> 0.11332363 | S4: =SUM(E4,F4)/O4 -> 4.5386792 | T4: =LOG10(E4+F4)*I4 -> 17.257445 | U4: =(K4/O4)*100 -> 0 | V4: =(L4/O4)*100 -> 0 | W4: =(M4/O4)*100 -> 0 | X4: =(N4/O4)*100 -> 0 | Y4: =E4/F4 -> 1.3074341 | Z4: =(SUM(E4,F4)/(K4+0.1))/100 -> 481.1 | AA4: =(SUM(E4,F4)/(L4+0.1))/100 -> 481.1 | AB4: =(SUM(E4,F4)/(M4+0.1))/100 -> 481.1 | AC4: =(SUM(E4,F4)/(N4+0.1))/100 -> 481.1
A5: =A4+1 -> 39 | B5: Restauración | C5: Abaceria del Postigo | D5: Tripadvisor | E5: 1593 | F5: 2211 | G5: 4.7 | H5: 4.9 | I5: =((G5*E5)+(H5*F5))/SUM(E5,F5) -> 4.8162461 | J5: 4 | K5: 0 | L5: 0 | M5: 0 | N5: =(K5*0.5)+(L5*0.4)+(M5*0.1) -> 0 | O5: 220 | P5: =ABS(G5-H5) -> 0.2 | Q5: =ABS(G5-I5) -> 0.11624606 | R5: =ABS(H5-I5) -> 0.083753943 | S5: =SUM(E5,F5)/O5 -> 17.290909 | T5: =LOG10(E5+F5)*I5 -> 17.243319 | U5: =(K5/O5)*100 -> 0 | V5: =(L5/O5)*100 -> 0 | W5: =(M5/O5)*100 -> 0 | X5: =(N5/O5)*100 -> 0 | Y5: =E5/F5 -> 0.72048847 | Z5: =(SUM(E5,F5)/(K5+0.1))/100 -> 380.4 | AA5: =(SUM(E5,F5)/(L5+0.1))/100 -> 380.4 | AB5: =(SUM(E5,F5)/(M5+0.1))/100 -> 380.4 | AC5: =(SUM(E5,F5)/(N5+0.1))/100 -> 380.4
A6: =A5+1 -> 40 | B6: Restauración | C6: Restaurante & Tapas El Sella | D6: Tripadvisor | E6: 4975 | F6: 6541 | G6: 4.7 | H6: 4.9 | I6: =((G6*E6)+(H6*F6))/SUM(E6,F6) -> 4.8135985 | J6: 5 | K6: 0 | L6: 0 | M6: 0 | N6: =(K6*0.5)+(L6*0.4)+(M6*0.1) -> 0 | O6: 908 | P6: =ABS(G6-H6) -> 0.2 | Q6: =ABS(G6-I6) -> 0.11359847 | R6: =ABS(H6-I6) -> 0.086401528 | S6: =SUM(E6,F6)/O6 -> 12.682819 | T6: =LOG10(E6+F6)*I6 -> 19.549475 | U6: =(K6/O6)*100 -> 0 | V6: =(L6/O6)*100 -> 0 | W6: =(M6/O6)*100 -> 0 | X6: =(N6/O6)*100 -> 0 | Y6: =E6/F6 -> 0.76058707 | Z6: =(SUM(E6,F6)/(K6+0.1))/100 -> 1151.6 | AA6: =(SUM(E6,F6)/(L6+0.1))/100 -> 1151.6 | AB6: =(SUM(E6,F6)/(M6+0.1))/100 -> 1151.6 | AC6: =(SUM(E6,F6)/(N6+0.1))/100 -> 1151.6
A7: =A6+1 -> 41 | B7: Restauración | C7: Gascona | D7: Tripadvisor | E7: 2753 | F7: 4410 | G7: 4.8 | H7: 4.9 | I7: =((G7*E7)+(H7*F7))/SUM(E7,F7) -> 4.8615664 | J7: 6 | K7: 13 | L7: 0 | M7: 0 | N7: =(K7*0.5)+(L7*0.4)+(M7*0.1) -> 6.5 | O7: 1080 | P7: =ABS(G7-H7) -> 0.1 | Q7: =ABS(G7-I7) -> 0.061566383 | R7: =ABS(H7-I7) -> 0.038433617 | S7: =SUM(E7,F7)/O7 -> 6.6324074 | T7: =LOG10(E7+F7)*I7 -> 18.7418 | U7: =(K7/O7)*100 -> 1.2037037 | V7: =(L7/O7)*100 -> 0 | W7: =(M7/O7)*100 -> 0 | X7: =(N7/O7)*100 -> 0.60185185 | Y7: =E7/F7 -> 0.62426304 | Z7: =(SUM(E7,F7)/(K7+0.1))/100 -> 5.4679389 | AA7: =(SUM(E7,F7)/(L7+0.1))/100 -> 716.3 | AB7: =(SUM(E7,F7)/(M7+0.1))/100 -> 716.3 | AC7: =(SUM(E7,F7)/(N7+0.1))/100 -> 10.85303
A8: =A7+1 -> 42 | B8: Restauración | C8: Sibuya Urban Sushi Bar Sevilla (Calle Albareda) | D8: Tripadvisor | E8: 4594 | F8: 7390 | G8: 4.5 | H8: 4.9 | I8: =((G8*E8)+(H8*F8))/SUM(E8,F8) -> 4.7466622 | J8: 7 | K8: 0 | L8: 0 | M8: 0 | N8: =(K8*0.5)+(L8*0.4)+(M8*0.1) -> 0 | O8: 446 | P8: =ABS(G8-H8) -> 0.4 | Q8: =ABS(G8-I8) -> 0.24666222 | R8: =ABS(H8-I8) -> 0.15333778 | S8: =SUM(E8,F8)/O8 -> 26.869955 | T8: =LOG10(E8+F8)*I8 -> 19.359745 | U8: =(K8/O8)*100 -> 0 | V8: =(L8/O8)*100 -> 0 | W8: =(M8/O8)*100 -> 0 | X8: =(N8/O8)*100 -> 0 | Y8: =E8/F8 -> 0.62165088 | Z8: =(SUM(E8,F8)/(K8+0.1))/100 -> 1198.4 | AA8: =(SUM(E8,F8)/(L8+0.1))/100 -> 1198.4 | AB8: =(SUM(E8,F8)/(M8+0.1))/100 -> 1198.4 | AC8: =(SUM(E8,F8)/(N8+0.1))/100 -> 1198.4
A9: =A8+1 -> 43 | B9: Restauración | C9: Brunchit (Calle Santa Patronas) | D9: Tripadvisor | E9: 3265 | F9: 643 | G9: 4.9 | H9: 4.9 | I9: =((G9*E9)+(H9*F9))/SUM(E9,F9) -> 4.9 | J9: 8 | K9: 0 | L9: 0 | M9: 0 | N9: =(K9*0.5)+(L9*0.4)+(M9*0.1) -> 0 | O9: 679 | P9: =ABS(G9-H9) -> 0 | Q9: =ABS(G9-I9) -> 0 | R9: =ABS(H9-I9) -> 0 | S9: =SUM(E9,F9)/O9 -> 5.7555228 | T9: =LOG10(E9+F9)*I9 -> 17.600577 | U9: =(K9/O9)*100 -> 0 | V9: =(L9/O9)*100 -> 0 | W9: =(M9/O9)*100 -> 0 | X9: =(N9/O9)*100 -> 0 | Y9: =E9/F9 -> 5.0777605 | Z9: =(SUM(E9,F9)/(K9+0.1))/100 -> 390.8 | AA9: =(SUM(E9,F9)/(L9+0.1))/100 -> 390.8 | AB9: =(SUM(E9,F9)/(M9+0.1))/100 -> 390.8 | AC9: =(SUM(E9,F9)/(N9+0.1))/100 -> 390.8
A10: =A9+1 -> 44 | B10: Restauración | C10: MareaViva | D10: Tripadvisor | E10: 2291 | F10: 3715 | G10: 4.4 | H10: 4.9 | I10: =((G10*E10)+(H10*F10))/SUM(E10,F10) -> 4.7092741 | J10: 9 | K10: 50 | L10: 50 | M10: 50 | N10: =(K10*0.5)+(L10*0.4)+(M10*0.1) -> 50 | O10: 1840 | P10: =ABS(G10-H10) -> 0.5 | Q10: =ABS(G10-I10) -> 0.30927406 | R10: =ABS(H10-I10) -> 0.19072594 | S10: =SUM(E10,F10)/O10 -> 3.2641304 | T10: =LOG10(E10+F10)*I10 -> 17.794394 | U10: =(K10/O10)*100 -> 2.7173913 | V10: =(L10/O10)*100 -> 2.7173913 | W10: =(M10/O10)*100 -> 2.7173913 | X10: =(N10/O10)*100 -> 2.7173913 | Y10: =E10/F10 -> 0.6166891 | Z10: =(SUM(E10,F10)/(K10+0.1))/100 -> 1.1988024 | AA10: =(SUM(E10,F10)/(L10+0.1))/100 -> 1.1988024 | AB10: =(SUM(E10,F10)/(M10+0.1))/100 -> 1.1988024 | AC10: =(SUM(E10,F10)/(N10+0.1))/100 -> 1.1988024
A11: =A10+1 -> 45 | B11: Restauración | C11: La Comilona | D11: Tripadvisor | E11: 2599 | F11: 2311 | G11: 4.3 | H11: 4.8 | I11: =((G11*E11)+(H11*F11))/SUM(E11,F11) -> 4.535336 | J11: 10 | K11: 100 | L11: 0 | M11: 16 | N11: =(K11*0.5)+(L11*0.4)+(M11*0.1) -> 51.6 | O11: 1870 | P11: =ABS(G11-H11) -> 0.5 | Q11: =ABS(G11-I11) -> 0.23533605 | R11: =ABS(H11-I11) -> 0.26466395 | S11: =SUM(E11,F11)/O11 -> 2.6256684 | T11: =LOG10(E11+F11)*I11 -> 16.740295 | U11: =(K11/O11)*100 -> 5.3475936 | V11: =(L11/O11)*100 -> 0 | W11: =(M11/O11)*100 -> 0.85561497 | X11: =(N11/O11)*100 -> 2.7593583 | Y11: =E11/F11 -> 1.1246214 | Z11: =(SUM(E11,F11)/(K11+0.1))/100 -> 0.49050949 | AA11: =(SUM(E11,F11)/(L11+0.1))/100 -> 491 | AB11: =(SUM(E11,F11)/(M11+0.1))/100 -> 3.0496894 | AC11: =(SUM(E11,F11)/(N11+0.1))/100 -> 0.94970986
A12: =A11+1 -> 46 | B12: Restauración | C12: Beirutina, Breakfast and Lunch | D12: Tripadvisor | E12: 967 | F12: 99 | G12: 4.9 | H12: 4.9 | I12: =((G12*E12)+(H12*F12))/SUM(E12,F12) -> 4.9 | J12: 12 | K12: 0 | L12: 0 | M12: 0 | N12: =(K12*0.5)+(L12*0.4)+(M12*0.1) -> 0 | O12: 773 | P12: =ABS(G12-H12) -> 0 | Q12: =ABS(G12-I12) -> 0 | R12: =ABS(H12-I12) -> 0 | S12: =SUM(E12,F12)/O12 -> 1.3790427 | T12: =LOG10(E12+F12)*I12 -> 14.83601 | U12: =(K12/O12)*100 -> 0 | V12: =(L12/O12)*100 -> 0 | W12: =(M12/O12)*100 -> 0 | X12: =(N12/O12)*100 -> 0 | Y12: =E12/F12 -> 9.7676768 | Z12: =(SUM(E12,F12)/(K12+0.1))/100 -> 106.6 | AA12: =(SUM(E12,F12)/(L12+0.1))/100 -> 106.6 | AB12: =(SUM(E12,F12)/(M12+0.1))/100 -> 106.6 | AC12: =(SUM(E12,F12)/(N12+0.1))/100 -> 106.6
A13: =A12+1 -> 47 | B13: Restauración | C13: Taberna de La Dehesa | D13: Tripadvisor | E13: 437 | F13: 674 | G13: 4 | H13: 4.7 | I13: =((G13*E13)+(H13*F13))/SUM(E13,F13) -> 4.4246625 | J13: 13 | K13: 33 | L13: 0 | M13: 0 | N13: =(K13*0.5)+(L13*0.4)+(M13*0.1) -> 16.5 | O13: 1750 | P13: =ABS(G13-H13) -> 0.7 | Q13: =ABS(G13-I13) -> 0.42466247 | R13: =ABS(H13-I13) -> 0.27533753 | S13: =SUM(E13,F13)/O13 -> 0.63485714 | T13: =LOG10(E13+F13)*I13 -> 13.476257 | U13: =(K13/O13)*100 -> 1.8857143 | V13: =(L13/O13)*100 -> 0 | W13: =(M13/O13)*100 -> 0 | X13: =(N13/O13)*100 -> 0.94285714 | Y13: =E13/F13 -> 0.64836795 | Z13: =(SUM(E13,F13)/(K13+0.1))/100 -> 0.33564955 | AA13: =(SUM(E13,F13)/(L13+0.1))/100 -> 111.1 | AB13: =(SUM(E13,F13)/(M13+0.1))/100 -> 111.1 | AC13: =(SUM(E13,F13)/(N13+0.1))/100 -> 0.66927711
A14: =A13+1 -> 48 | B14: Restauración | C14: Il Ristorantino Dell' Avvocato (Calle Regina) | D14: Tripadvisor | E14: 5845 | F14: 1658 | G14: 4.8 | H14: 4.8 | I14: =((G14*E14)+(H14*F14))/SUM(E14,F14) -> 4.8 | J14: 14 | K14: 50 | L14: 0 | M14: 0 | N14: =(K14*0.5)+(L14*0.4)+(M14*0.1) -> 25 | O14: 910 | P14: =ABS(G14-H14) -> 0 | Q14: =ABS(G14-I14) -> 0 | R14: =ABS(H14-I14) -> 0 | S14: =SUM(E14,F14)/O14 -> 8.2450549 | T14: =LOG10(E14+F14)*I14 -> 18.601128 | U14: =(K14/O14)*100 -> 5.4945055 | V14: =(L14/O14)*100 -> 0 | W14: =(M14/O14)*100 -> 0 | X14: =(N14/O14)*100 -> 2.7472527 | Y14: =E14/F14 -> 3.5253317 | Z14: =(SUM(E14,F14)/(K14+0.1))/100 -> 1.4976048 | AA14: =(SUM(E14,F14)/(L14+0.1))/100 -> 750.3 | AB14: =(SUM(E14,F14)/(M14+0.1))/100 -> 750.3 | AC14: =(SUM(E14,F14)/(N14+0.1))/100 -> 2.989243
